[2024-11-11 15:32:37 +0200] [1952] [INFO] Starting gunicorn 22.0.0
[2024-11-11 15:32:37 +0200] [1952] [INFO] Listening at: http://127.0.0.1:8000 (1952)
[2024-11-11 15:32:37 +0200] [1952] [INFO] Using worker: sync
[2024-11-11 15:32:37 +0200] [1953] [INFO] Starting gunicorn 22.0.0
[2024-11-11 15:32:37 +0200] [1953] [ERROR] Connection in use: ('127.0.0.1', 8000)
[2024-11-11 15:32:37 +0200] [1953] [ERROR] Retrying in 1 second.
[2024-11-11 15:32:37 +0200] [1956] [INFO] Booting worker with pid: 1956
[2024-11-11 15:32:37 +0200] [1956] [ERROR] Exception in worker process
Traceback (most recent call last):
  File "/home/mugisha/.local/lib/python3.8/site-packages/gunicorn/arbiter.py", line 609, in spawn_worker
    worker.init_process()
  File "/home/mugisha/.local/lib/python3.8/site-packages/gunicorn/workers/base.py", line 134, in init_process
    self.load_wsgi()
  File "/home/mugisha/.local/lib/python3.8/site-packages/gunicorn/workers/base.py", line 146, in load_wsgi
    self.wsgi = self.app.wsgi()
  File "/home/mugisha/.local/lib/python3.8/site-packages/gunicorn/app/base.py", line 67, in wsgi
    self.callable = self.load()
  File "/home/mugisha/.local/lib/python3.8/site-packages/gunicorn/app/wsgiapp.py", line 58, in load
    return self.load_wsgiapp()
  File "/home/mugisha/.local/lib/python3.8/site-packages/gunicorn/app/wsgiapp.py", line 48, in load_wsgiapp
    return util.import_app(self.app_uri)
  File "/home/mugisha/.local/lib/python3.8/site-packages/gunicorn/util.py", line 371, in import_app
    mod = importlib.import_module(module)
  File "/usr/lib/python3.8/importlib/__init__.py", line 127, in import_module
    return _bootstrap._gcd_import(name[level:], package, level)
  File "<frozen importlib._bootstrap>", line 1014, in _gcd_import
  File "<frozen importlib._bootstrap>", line 991, in _find_and_load
  File "<frozen importlib._bootstrap>", line 973, in _find_and_load_unlocked
ModuleNotFoundError: No module named 'app'
[2024-11-11 15:32:37 +0200] [1956] [INFO] Worker exiting (pid: 1956)
[2024-11-11 15:32:37 +0200] [1957] [INFO] Booting worker with pid: 1957
[2024-11-11 15:32:37 +0200] [1952] [ERROR] Worker (pid:1956) exited with code 3
[2024-11-11 15:32:37 +0200] [1957] [ERROR] Exception in worker process
Traceback (most recent call last):
  File "/home/mugisha/.local/lib/python3.8/site-packages/gunicorn/arbiter.py", line 609, in spawn_worker
    worker.init_process()
  File "/home/mugisha/.local/lib/python3.8/site-packages/gunicorn/workers/base.py", line 134, in init_process
    self.load_wsgi()
  File "/home/mugisha/.local/lib/python3.8/site-packages/gunicorn/workers/base.py", line 146, in load_wsgi
    self.wsgi = self.app.wsgi()
  File "/home/mugisha/.local/lib/python3.8/site-packages/gunicorn/app/base.py", line 67, in wsgi
    self.callable = self.load()
  File "/home/mugisha/.local/lib/python3.8/site-packages/gunicorn/app/wsgiapp.py", line 58, in load
    return self.load_wsgiapp()
  File "/home/mugisha/.local/lib/python3.8/site-packages/gunicorn/app/wsgiapp.py", line 48, in load_wsgiapp
    return util.import_app(self.app_uri)
  File "/home/mugisha/.local/lib/python3.8/site-packages/gunicorn/util.py", line 371, in import_app
    mod = importlib.import_module(module)
  File "/usr/lib/python3.8/importlib/__init__.py", line 127, in import_module
    return _bootstrap._gcd_import(name[level:], package, level)
  File "<frozen importlib._bootstrap>", line 1014, in _gcd_import
  File "<frozen importlib._bootstrap>", line 991, in _find_and_load
  File "<frozen importlib._bootstrap>", line 973, in _find_and_load_unlocked
ModuleNotFoundError: No module named 'app'
[2024-11-11 15:32:37 +0200] [1957] [INFO] Worker exiting (pid: 1957)
[2024-11-11 15:32:37 +0200] [1952] [ERROR] Worker (pid:1957) exited with code 3
Traceback (most recent call last):
  File "/home/mugisha/.local/lib/python3.8/site-packages/gunicorn/arbiter.py", line 202, in run
    self.manage_workers()
  File "/home/mugisha/.local/lib/python3.8/site-packages/gunicorn/arbiter.py", line 571, in manage_workers
    self.spawn_workers()
  File "/home/mugisha/.local/lib/python3.8/site-packages/gunicorn/arbiter.py", line 643, in spawn_workers
    time.sleep(0.1 * random.random())
  File "/home/mugisha/.local/lib/python3.8/site-packages/gunicorn/arbiter.py", line 242, in handle_chld
    self.reap_workers()
  File "/home/mugisha/.local/lib/python3.8/site-packages/gunicorn/arbiter.py", line 530, in reap_workers
    raise HaltServer(reason, self.WORKER_BOOT_ERROR)
gunicorn.errors.HaltServer: <HaltServer 'Worker failed to boot.' 3>

During handling of the above exception, another exception occurred:

Traceback (most recent call last):
  File "/home/mugisha/.local/bin/gunicorn", line 8, in <module>
    sys.exit(run())
  File "/home/mugisha/.local/lib/python3.8/site-packages/gunicorn/app/wsgiapp.py", line 67, in run
    WSGIApplication("%(prog)s [OPTIONS] [APP_MODULE]", prog=prog).run()
  File "/home/mugisha/.local/lib/python3.8/site-packages/gunicorn/app/base.py", line 236, in run
    super().run()
  File "/home/mugisha/.local/lib/python3.8/site-packages/gunicorn/app/base.py", line 72, in run
    Arbiter(self).run()
  File "/home/mugisha/.local/lib/python3.8/site-packages/gunicorn/arbiter.py", line 229, in run
    self.halt(reason=inst.reason, exit_status=inst.exit_status)
  File "/home/mugisha/.local/lib/python3.8/site-packages/gunicorn/arbiter.py", line 342, in halt
    self.stop()
  File "/home/mugisha/.local/lib/python3.8/site-packages/gunicorn/arbiter.py", line 396, in stop
    time.sleep(0.1)
  File "/home/mugisha/.local/lib/python3.8/site-packages/gunicorn/arbiter.py", line 242, in handle_chld
    self.reap_workers()
  File "/home/mugisha/.local/lib/python3.8/site-packages/gunicorn/arbiter.py", line 530, in reap_workers
    raise HaltServer(reason, self.WORKER_BOOT_ERROR)
gunicorn.errors.HaltServer: <HaltServer 'Worker failed to boot.' 3>
[2024-11-11 15:32:38 +0200] [1953] [INFO] Listening at: http://127.0.0.1:8000 (1953)
[2024-11-11 15:32:38 +0200] [1953] [INFO] Using worker: sync
[2024-11-11 15:32:38 +0200] [1958] [INFO] Booting worker with pid: 1958
[2024-11-11 15:32:38 +0200] [1958] [ERROR] Exception in worker process
Traceback (most recent call last):
  File "/home/mugisha/.local/lib/python3.8/site-packages/gunicorn/arbiter.py", line 609, in spawn_worker
    worker.init_process()
  File "/home/mugisha/.local/lib/python3.8/site-packages/gunicorn/workers/base.py", line 134, in init_process
    self.load_wsgi()
  File "/home/mugisha/.local/lib/python3.8/site-packages/gunicorn/workers/base.py", line 146, in load_wsgi
    self.wsgi = self.app.wsgi()
  File "/home/mugisha/.local/lib/python3.8/site-packages/gunicorn/app/base.py", line 67, in wsgi
    self.callable = self.load()
  File "/home/mugisha/.local/lib/python3.8/site-packages/gunicorn/app/wsgiapp.py", line 58, in load
    return self.load_wsgiapp()
  File "/home/mugisha/.local/lib/python3.8/site-packages/gunicorn/app/wsgiapp.py", line 48, in load_wsgiapp
    return util.import_app(self.app_uri)
  File "/home/mugisha/.local/lib/python3.8/site-packages/gunicorn/util.py", line 371, in import_app
    mod = importlib.import_module(module)
  File "/usr/lib/python3.8/importlib/__init__.py", line 127, in import_module
    return _bootstrap._gcd_import(name[level:], package, level)
  File "<frozen importlib._bootstrap>", line 1014, in _gcd_import
  File "<frozen importlib._bootstrap>", line 991, in _find_and_load
  File "<frozen importlib._bootstrap>", line 973, in _find_and_load_unlocked
ModuleNotFoundError: No module named 'app'
[2024-11-11 15:32:38 +0200] [1958] [INFO] Worker exiting (pid: 1958)
[2024-11-11 15:32:38 +0200] [1953] [ERROR] Worker (pid:1958) exited with code 3
[2024-11-11 15:32:38 +0200] [1953] [ERROR] Shutting down: Master
[2024-11-11 15:32:38 +0200] [1953] [ERROR] Reason: Worker failed to boot.
[2024-11-11 15:33:13 +0200] [1961] [INFO] Starting gunicorn 22.0.0
[2024-11-11 15:33:13 +0200] [1961] [INFO] Listening at: http://127.0.0.1:8000 (1961)
[2024-11-11 15:33:13 +0200] [1961] [INFO] Using worker: sync
[2024-11-11 15:33:13 +0200] [1960] [INFO] Starting gunicorn 22.0.0
[2024-11-11 15:33:13 +0200] [1960] [ERROR] Connection in use: ('127.0.0.1', 8000)
[2024-11-11 15:33:13 +0200] [1960] [ERROR] Retrying in 1 second.
[2024-11-11 15:33:13 +0200] [1964] [INFO] Booting worker with pid: 1964
[2024-11-11 15:33:13 +0200] [1964] [ERROR] Exception in worker process
Traceback (most recent call last):
  File "/home/mugisha/.local/lib/python3.8/site-packages/gunicorn/arbiter.py", line 609, in spawn_worker
    worker.init_process()
  File "/home/mugisha/.local/lib/python3.8/site-packages/gunicorn/workers/base.py", line 134, in init_process
    self.load_wsgi()
  File "/home/mugisha/.local/lib/python3.8/site-packages/gunicorn/workers/base.py", line 146, in load_wsgi
    self.wsgi = self.app.wsgi()
  File "/home/mugisha/.local/lib/python3.8/site-packages/gunicorn/app/base.py", line 67, in wsgi
    self.callable = self.load()
  File "/home/mugisha/.local/lib/python3.8/site-packages/gunicorn/app/wsgiapp.py", line 58, in load
    return self.load_wsgiapp()
  File "/home/mugisha/.local/lib/python3.8/site-packages/gunicorn/app/wsgiapp.py", line 48, in load_wsgiapp
    return util.import_app(self.app_uri)
  File "/home/mugisha/.local/lib/python3.8/site-packages/gunicorn/util.py", line 371, in import_app
    mod = importlib.import_module(module)
  File "/usr/lib/python3.8/importlib/__init__.py", line 127, in import_module
    return _bootstrap._gcd_import(name[level:], package, level)
  File "<frozen importlib._bootstrap>", line 1014, in _gcd_import
  File "<frozen importlib._bootstrap>", line 991, in _find_and_load
  File "<frozen importlib._bootstrap>", line 973, in _find_and_load_unlocked
ModuleNotFoundError: No module named 'app'
[2024-11-11 15:33:13 +0200] [1964] [INFO] Worker exiting (pid: 1964)
[2024-11-11 15:33:13 +0200] [1961] [ERROR] Worker (pid:1964) exited with code 3
[2024-11-11 15:33:13 +0200] [1961] [ERROR] Shutting down: Master
[2024-11-11 15:33:13 +0200] [1961] [ERROR] Reason: Worker failed to boot.
[2024-11-11 15:33:14 +0200] [1960] [INFO] Listening at: http://127.0.0.1:8000 (1960)
[2024-11-11 15:33:14 +0200] [1960] [INFO] Using worker: sync
[2024-11-11 15:33:14 +0200] [1965] [INFO] Booting worker with pid: 1965
[2024-11-11 15:33:14 +0200] [1965] [ERROR] Exception in worker process
Traceback (most recent call last):
  File "/home/mugisha/.local/lib/python3.8/site-packages/gunicorn/arbiter.py", line 609, in spawn_worker
    worker.init_process()
  File "/home/mugisha/.local/lib/python3.8/site-packages/gunicorn/workers/base.py", line 134, in init_process
    self.load_wsgi()
  File "/home/mugisha/.local/lib/python3.8/site-packages/gunicorn/workers/base.py", line 146, in load_wsgi
    self.wsgi = self.app.wsgi()
  File "/home/mugisha/.local/lib/python3.8/site-packages/gunicorn/app/base.py", line 67, in wsgi
    self.callable = self.load()
  File "/home/mugisha/.local/lib/python3.8/site-packages/gunicorn/app/wsgiapp.py", line 58, in load
    return self.load_wsgiapp()
  File "/home/mugisha/.local/lib/python3.8/site-packages/gunicorn/app/wsgiapp.py", line 48, in load_wsgiapp
    return util.import_app(self.app_uri)
  File "/home/mugisha/.local/lib/python3.8/site-packages/gunicorn/util.py", line 371, in import_app
    mod = importlib.import_module(module)
  File "/usr/lib/python3.8/importlib/__init__.py", line 127, in import_module
    return _bootstrap._gcd_import(name[level:], package, level)
  File "<frozen importlib._bootstrap>", line 1014, in _gcd_import
  File "<frozen importlib._bootstrap>", line 991, in _find_and_load
  File "<frozen importlib._bootstrap>", line 973, in _find_and_load_unlocked
ModuleNotFoundError: No module named 'app'
[2024-11-11 15:33:14 +0200] [1965] [INFO] Worker exiting (pid: 1965)
[2024-11-11 15:33:14 +0200] [1960] [ERROR] Worker (pid:1965) exited with code 3
[2024-11-11 15:33:14 +0200] [1960] [ERROR] Shutting down: Master
[2024-11-11 15:33:14 +0200] [1960] [ERROR] Reason: Worker failed to boot.
